<?xml version="1.0"?>
<robot xmlns:xacro="http://www.ros.org/wiki/xacro" name="robot">

    <!-- Load Simulated or Real Hardware Interfaces -->
    <xacro:arg name="is_sim" default="true"/>

    <xacro:include filename="inertial_macros.xacro"/>
    <!-- <xacro:include filename="gazebo_control.xacro"/> -->
    <xacro:include filename="lidar.xacro"/>
    <xacro:include filename="ros2_control.xacro"/>

    <material name="white">
        <color rgba="1 1 1 1" />
    </material>

    <material name="orange">
        <color rgba="1 0.3 0.1 1" />
    </material>

    <material name="blue">
        <color rgba="0.2 0.2 1 1" />
    </material>

    <material name="black">
        <color rgba="0 0 0 1" />
    </material>

    <material name="red">
        <color rgba="1 0 0 1" />
    </material>


    <!-- BASE LINK -->

    <link name="base_link">

    </link>

    <!-- CHASSIS LINK -->

    <joint name="chassis_joint" type="fixed">
        <parent link = "base_link"/>
        <child link="chassis"/>
        <origin xyz="-0.1 0 0"/>
    </joint>

    <link name="chassis">
        <visual>
            <origin xyz="0.12 0 0.035"/>
            <geometry>
                <box size="0.24 0.2 0.07"/>
            </geometry>
            <material name="white"/>
        </visual>
        <collision>
            <origin xyz="0.12 0 0.035"/>
            <geometry>
                <box size="0.24 0.2 0.07"/>
            </geometry>
        </collision>
        <xacro:inertial_box mass="0.5" x="0.24" y="0.2" z="0.07">
            <origin xyz="0.12 0 0.035" rpy="0 0 0"/>
        </xacro:inertial_box>
    </link>

    <gazebo reference="chassis">
        <material>Gazebo/White</material>
    </gazebo>

    <!-- LIDAR BASE LINK -->

    <joint name="lidar_joint" type="fixed">
        <parent link = "chassis"/>
        <child link="lidar_base"/>
        <origin xyz="0.0375 0 0.07"/>
    </joint>

    <link name="lidar_base">
        <visual>
            <origin xyz="0.0 0 0.015"/>
            <geometry>
                <box size="0.075 0.07 0.03"/>
            </geometry>
            <material name="white"/>
        </visual>
        <collision>
            <origin xyz="0 0 0.015"/>
            <geometry>
                <box size="0.075 0.07 0.03"/>
            </geometry>
        </collision>
        <xacro:inertial_box mass="0.5" x="0.075" y="0.07" z="0.03">
            <origin xyz="0.0 0 0.015" rpy="0 0 0"/>
        </xacro:inertial_box>
    </link>

    <gazebo reference="chassis">
        <material>Gazebo/White</material>
    </gazebo>

    <!-- LEFT WHEEL LINK -->

    <joint name="left_wheel_joint" type="continuous">
        <parent link="base_link"/>
        <child link="left_wheel"/>
        <origin xyz="-0.055 0.12 0" rpy="-${pi/2} 0 0"/>
        <axis xyz="0 0 1"/>
    </joint>

    <link name="left_wheel">
        <visual>
            <geometry>
                <cylinder radius="0.0425" length="0.04"/>
            </geometry>
            <material name="blue"/>
        </visual>
        <collision>
            <geometry>
                <sphere radius="0.0425"/>
                <!-- <cylinder radius="0.0425" length="0.04"/> -->
            </geometry>
        </collision>
        <xacro:inertial_cylinder mass="0.1" length="0.04" radius="0.0425">
            <origin xyz="0 0 0" rpy="0 0 0"/>
        </xacro:inertial_cylinder>
    </link>

    <gazebo reference="left_wheel">
        <material>Gazebo/Blue</material> -->
    </gazebo>

    <!-- RIGHT WHEEL LINK-->

    <joint name="right_wheel_joint" type="continuous">
        <parent link="base_link"/>
        <child link="right_wheel"/>
        <origin xyz="-0.055 -0.12 0" rpy="${pi/2} 0 0"/>
        <axis xyz="0 0 -1"/>
    </joint>

    <link name="right_wheel">
        <visual>
            <geometry>
                <cylinder radius="0.0425" length="0.04"/>
            </geometry>
            <material name="blue"/>
        </visual>
        <collision>
            <geometry>
                <sphere radius="0.0425"/>
                <!-- <cylinder radius="0.0425" length="0.04"/> -->
            </geometry>
        </collision>
        <xacro:inertial_cylinder mass="0.1" length="0.04" radius="0.0425">
            <origin xyz="0 0 0" rpy="0 0 0"/>
        </xacro:inertial_cylinder>
    </link>

    <gazebo reference="right_wheel">
        <material>Gazebo/Blue</material>
    </gazebo>

    <!--CASTOR WHEEL LINK-->

    <joint name="caster_wheel_joint" type="fixed">
        <parent link="chassis"/>
        <child link="castor_wheel"/>
        <origin xyz="0.18 0 0"/>
    </joint>

    <link name="castor_wheel">
        <visual>
            <geometry>
                <sphere radius="0.05"/>
            </geometry>
            <material name="black"/>
        </visual>
        <collision>
            <geometry>
                <sphere radius="0.04"/>
            </geometry>
        </collision>
        <xacro:inertial_sphere mass="0.1" radius="0.04">
            <origin xyz="0 0 0" rpy="0 0 0"/>
        </xacro:inertial_sphere>
    </link>

    <gazebo reference="castor_wheel">
        <material>Gazebo/Black</material>
        <mu1 value="0.001"/>
        <mu2 value="0.001"/>
    </gazebo>

</robot>